Workbook

Sheet Übersicht
A1: Wangerooge West – Landmarkenliste
A2: Version 1.2 vom 11.10.2026 (neue Symbole und Landmarken) · Kartenrahmen UTM32 E 423750–427150, N 5958850–5961650 · Start: Inselheim Rüstringen mit Sternwarte
A4: Status „sicher“ = mindestens zwei unabhängige Quellen. „prüfen“ = nur eine Quelle; in der Karte grau, auf der Feldcheck-Seite als weißer Marker. IDs sind ab Version 1.1 stabil.
A6: Kategorie | B6: sicher | C6: prüfen | D6: gesamt
A7: Unterkunft | B7: =COUNTIFS(Landmarken!$B$2:$B$885,$A7,Landmarken!$E$2:$E$885,"sicher") | C7: =COUNTIFS(Landmarken!$B$2:$B$885,$A7,Landmarken!$E$2:$E$885,"prüfen") | D7: =B7+C7
A8: Bauwerk | B8: =COUNTIFS(Landmarken!$B$2:$B$885,$A8,Landmarken!$E$2:$E$885,"sicher") | C8: =COUNTIFS(Landmarken!$B$2:$B$885,$A8,Landmarken!$E$2:$E$885,"prüfen") | D8: =B8+C8
A9: Gastronomie | B9: =COUNTIFS(Landmarken!$B$2:$B$885,$A9,Landmarken!$E$2:$E$885,"sicher") | C9: =COUNTIFS(Landmarken!$B$2:$B$885,$A9,Landmarken!$E$2:$E$885,"prüfen") | D9: =B9+C9
A10: Historisch | B10: =COUNTIFS(Landmarken!$B$2:$B$885,$A10,Landmarken!$E$2:$E$885,"sicher") | C10: =COUNTIFS(Landmarken!$B$2:$B$885,$A10,Landmarken!$E$2:$E$885,"prüfen") | D10: =B10+C10
A11: Gebäude | B11: =COUNTIFS(Landmarken!$B$2:$B$885,$A11,Landmarken!$E$2:$E$885,"sicher") | C11: =COUNTIFS(Landmarken!$B$2:$B$885,$A11,Landmarken!$E$2:$E$885,"prüfen") | D11: =B11+C11
A12: Einrichtung | B12: =COUNTIFS(Landmarken!$B$2:$B$885,$A12,Landmarken!$E$2:$E$885,"sicher") | C12: =COUNTIFS(Landmarken!$B$2:$B$885,$A12,Landmarken!$E$2:$E$885,"prüfen") | D12: =B12+C12
A13: Gelände | B13: =COUNTIFS(Landmarken!$B$2:$B$885,$A13,Landmarken!$E$2:$E$885,"sicher") | C13: =COUNTIFS(Landmarken!$B$2:$B$885,$A13,Landmarken!$E$2:$E$885,"prüfen") | D13: =B13+C13
A14: Gewässer | B14: =COUNTIFS(Landmarken!$B$2:$B$885,$A14,Landmarken!$E$2:$E$885,"sicher") | C14: =COUNTIFS(Landmarken!$B$2:$B$885,$A14,Landmarken!$E$2:$E$885,"prüfen") | D14: =B14+C14
A15: Vegetation | B15: =COUNTIFS(Landmarken!$B$2:$B$885,$A15,Landmarken!$E$2:$E$885,"sicher") | C15: =COUNTIFS(Landmarken!$B$2:$B$885,$A15,Landmarken!$E$2:$E$885,"prüfen") | D15: =B15+C15
A16: Dünenübergang | B16: =COUNTIFS(Landmarken!$B$2:$B$885,$A16,Landmarken!$E$2:$E$885,"sicher") | C16: =COUNTIFS(Landmarken!$B$2:$B$885,$A16,Landmarken!$E$2:$E$885,"prüfen") | D16: =B16+C16
A17: Durchgang | B17: =COUNTIFS(Landmarken!$B$2:$B$885,$A17,Landmarken!$E$2:$E$885,"sicher") | C17: =COUNTIFS(Landmarken!$B$2:$B$885,$A17,Landmarken!$E$2:$E$885,"prüfen") | D17: =B17+C17
A18: Rettungspunkt | B18: =COUNTIFS(Landmarken!$B$2:$B$885,$A18,Landmarken!$E$2:$E$885,"sicher") | C18: =COUNTIFS(Landmarken!$B$2:$B$885,$A18,Landmarken!$E$2:$E$885,"prüfen") | D18: =B18+C18
... A35: Steilhang | B35: =COUNTIFS(Landmarken!$B$2:$B$885,$A35,Landmarken!$E$2:$E$885,"sicher") | C35: =COUNTIFS(Landmarken!$B$2:$B$885,$A35,Landmarken!$E$2:$E$885,"prüfen") | D35: =B35+C35
A36: Pfade (Luftbild unklar) | B36: 0 | C36: =COUNTA('Pfade prüfen'!A2:A25) | D36: =B36+C36
A37: Summe | B37: =SUM(B7:B36) | C37: =SUM(C7:C36) | D37: =SUM(D7:D36)
A39: Quellen
A40: OpenStreetMap (Abruf 11.10.2026) | B40: © OpenStreetMap-Mitwirkende, ODbL – Wege, Gebäude, Bänke, POIs, Ruhezone I/32
A41: LGLN DGM1 (Befliegung 2022) | B41: LGLN (2026), CC BY 4.0 – Höhenlinien, Gruben/Trichter, Aussichtsdüne
A42: LGLN DOP20 (Befliegung 19.10.2025) | B42: LGLN (2026), CC BY 4.0 – Bank-/Trichterabgleich, Sandflächen, Pfadsichtbarkeit, Lage Sternwarte
A43: aloeus.de, Wikipedia, TracesOfWar, gruppenhaus.de | B43: Zweitquellen für Sternwarte, Westturm, Leuchtturm, Kriegsgräberstätte, Heime
A44: Hinweis | B44: Ruhezonen-Grenze stammt aus OSM (aus der Seekarte übernommen); vor Ort an den Schildern prüfen.

Sheet Landmarken
A1: ID | B1: Kategorie | C1: Typ | D1: Name | E1: Status | F1: Quellen | G1: Breite (WGS84) | H1: Länge (WGS84) | I1: UTM32 Ost (m) | J1: UTM32 Nord (m) | K1: Zone | L1: Notiz | M1: OSM-ID
A2: BU010 | B2: Bahnübergang | C2: crossing | E2: sicher | F2: OSM + Luftbild | G2: 53.791295 | H2: 7.874119 | I2: 425831.8 | J2: 5960889.4 | L2: Weg kreuzt die Inselbahn | M2: n538730564
A3: BU011 | B3: Bahnübergang | C3: level_crossing | E3: sicher | F3: OSM + Luftbild | G3: 53.788773 | H3: 7.850818 | I3: 424292.4 | J3: 5960633.5 | L3: Weg kreuzt die Inselbahn | M3: n538730562
A4: BU012 | B4: Bahnübergang | C4: crossing | E4: sicher | F4: OSM + Luftbild | G4: 53.788325 | H4: 7.890977 | I4: 426937.1 | J4: 5960541.6 | L4: Weg kreuzt die Inselbahn | M4: n613218684
A5: BU013 | B5: Bahnübergang | C5: crossing | E5: sicher | F5: OSM + Luftbild | G5: 53.78749 | H5: 7.893716 | I5: 427116.1 | J5: 5960445.8 | L5: Weg kreuzt die Inselbahn | M5: n325153870
A6: BU014 | B6: Bahnübergang | C6: crossing | E6: sicher | F6: OSM + Luftbild | G6: 53.776531 | H6: 7.867915 | I6: 425397 | J6: 5959253.5 | L6: Weg kreuzt die Inselbahn | M6: n6401369308
A7: BU017 | B7: Bahnübergang | C7: crossing | E7: sicher | F7: OSM + Luftbild | G7: 53.774306 | H7: 7.866822 | I7: 425321 | J7: 5959007.1 | L7: Weg kreuzt die Inselbahn | M7: n4624140713
A8: BK001 | B8: Bank | C8: Bank | E8: prüfen | F8: OSM; im Luftbild unsicher | G8: 53.793185 | H8: 7.870684 | I8: 425608.8 | J8: 5961103.3 | L8: backrest=no | M8: n2322972140
A9: BK002 | B9: Bank | C9: Bank | E9: sicher | F9: OSM + Luftbild | G9: 53.792777 | H9: 7.868116 | I9: 425439 | J9: 5961060.6 | L9: backrest=yes | M9: n2322972139
A10: BK003 | B10: Bank | C10: Bank | E10: prüfen | F10: OSM; im Luftbild unsicher | G10: 53.793028 | H10: 7.870007 | I10: 425564 | J10: 5961086.5 | L10: backrest=yes | M10: n2322975870
A11: BK004 | B11: Bank | C11: Bank | E11: sicher | F11: OSM + Luftbild | G11: 53.792951 | H11: 7.873085 | I11: 425766.6 | J11: 5961074.8 | L11: backrest=yes | M11: n2322975867
A12: BK005 | B12: Bank | C12: Bank | E12: prüfen | F12: OSM; im Luftbild nicht erkennbar | G12: 53.793016 | H12: 7.874719 | I12: 425874.4 | J12: 5961080.3 | L12: backrest=yes, material=wood | M12: n2322975869
A13: BK006 | B13: Bank | C13: Bank | E13: prüfen | F13: OSM; im Luftbild unsicher | G13: 53.792337 | H13: 7.875453 | I13: 425921.5 | J13: 5961003.9 | L13: backrest=no, material=wood | M13: n743377534
... A28: BK021 | B28: Bank | C28: Bank | E28: sicher | F28: OSM + Luftbild | G28: 53.791102 | H28: 7.859397 | I28: 424861.7 | J28: 5960883.5 | L28: backrest=no | M28: n2322176440
A29: BK022 | B29: Bank | C29: Bank | E29: sicher | F29: OSM + Luftbild | G29: 53.790878 | H29: 7.871621 | I29: 425666.5 | J29: 5960845.7 | K29: Ruhezone I/32 | L29: backrest=yes, seats=4 | M29: n12504080887
A30: BK023 | B30: Bank | C30: Bank | E30: sicher | F30: OSM + Luftbild | G30: 53.790873 | H30: 7.871663 | I30: 425669.3 | J30: 5960845.1 | K30: Ruhezone I/32 | L30: backrest=yes, seats=4 | M30: n1431891144
A31: BK024 | B31: Bank | C31: Bank | E31: prüfen | F31: OSM; im Luftbild nicht erkennbar | G31: 53.790965 | H31: 7.880035 | I31: 426220.9 | J31: 5960846.6 | L31: backrest=yes | M31: n1430929569
A32: BK025 | B32: Bank | C32: Bank | E32: prüfen | F32: OSM; im Luftbild unsicher | G32: 53.790988 | H32: 7.883745 | I32: 426465.4 | J32: 5960845.3 | L32: backrest=yes, material=wood | M32: n1430929571
A33: BK026 | B33: Bank | C33: Bank | E33: prüfen | F33: OSM; im Luftbild unsicher | G33: 53.791468 | H33: 7.8887 | I33: 426792.6 | J33: 5960893.5 | L33: backrest=no | M33: n2322997548
A34: BK027 | B34: Bank | C34: Bank | E34: prüfen | F34: OSM; im Luftbild nicht erkennbar | G34: 53.791364 | H34: 7.892359 | I34: 427033.5 | J34: 5960878.2 | L34: backrest=no | M34: n2322997540
A35: BK028 | B35: Bank | C35: Bank | E35: prüfen | F35: OSM; im Luftbild nicht erkennbar | G35: 53.791548 | H35: 7.893575 | I35: 427113.9 | J35: 5960897.5 | L35: backrest=yes | M35: n2319753490
A36: BK029 | B36: Bank | C36: Bank | E36: sicher | F36: OSM + Luftbild | G36: 53.789557 | H36: 7.852876 | I36: 424429.3 | J36: 5960718.5 | L36: backrest=yes, material=plastic | M36: n2322151573
A37: BK030 | B37: Bank | C37: Bank | E37: prüfen | F37: OSM; im Luftbild nicht erkennbar | G37: 53.789972 | H37: 7.854537 | I37: 424539.5 | J37: 5960762.9 | M37: n1431891143
A38: BK031 | B38: Bank | C38: Bank | E38: prüfen | F38: OSM; im Luftbild nicht erkennbar | G38: 53.790307 | H38: 7.856728 | I38: 424684.4 | J38: 5960797.9 | L38: backrest=no | M38: n743377607
A39: BK032 | B39: Bank | C39: Bank | E39: prüfen | F39: OSM; im Luftbild unsicher | G39: 53.790051 | H39: 7.857223 | I39: 424716.6 | J39: 5960768.8 | L39: backrest=yes | M39: n3670463635
A40: BK033 | B40: Bank | C40: Bank | E40: prüfen | F40: OSM; im Luftbild nicht erkennbar | G40: 53.78987 | H40: 7.86656 | I40: 425331.3 | J40: 5960738.8 | K40: Ruhezone I/32 | L40: backrest=yes | M40: n1431891141
A41: BK034 | B41: Bank | C41: Bank | E41: sicher | F41: OSM + Luftbild | G41: 53.790025 | H41: 7.878357 | I41: 426108.7 | J41: 5960743.8 | L41: backrest=yes, check_date=2023-04-10, seats=4 | M41: n1385089137
A42: BK035 | B42: Bank | C42: Bank | E42: sicher | F42: OSM + Luftbild | G42: 53.790017 | H42: 7.878408 | I42: 426112.1 | J42: 5960742.8 | L42: backrest=yes, check_date=2023-04-10, seats=4 | M42: n1385089135
A43: BK036 | B43: Bank | C43: Bank | E43: sicher | F43: OSM + Luftbild | G43: 53.788394 | H43: 7.892281 | I43: 427023.1 | J43: 5960547.9 | L43: backrest=yes, material=wood | M43: n1430929567
A44: BK037 | B44: Bank | C44: Bank | E44: sicher | F44: OSM + Luftbild | G44: 53.788307 | H44: 7.892543 | I44: 427040.3 | J44: 5960537.9 | L44: backrest=yes, material=wood | M44: n2323231690
A45: BK038 | B45: Bank | C45: Bank | E45: prüfen | F45: OSM; im Luftbild nicht erkennbar | G45: 53.786759 | H45: 7.848822 | I45: 424157.2 | J45: 5960411.6 | L45: backrest=yes, check_date=2026-07-24, material=wood, seats=4 | M45: n6549301866
A46: BK039 | B46: Bank | C46: Bank | E46: prüfen | F46: OSM; im Luftbild unsicher | G46: 53.787216 | H46: 7.850913 | I46: 424295.8 | J46: 5960460.2 | L46: backrest=yes | M46: n2322032111
A47: BK040 | B47: Bank | C47: Bank | E47: prüfen | F47: OSM; im Luftbild nicht erkennbar | G47: 53.785959 | H47: 7.849934 | I47: 424229 | J47: 5960321.4 | L47: backrest=yes, material=wood | M47: n2323592758
A48: BK041 | B48: Bank | C48: Bank | E48: prüfen | F48: OSM; im Luftbild nicht erkennbar | G48: 53.785904 | H48: 7.850029 | I48: 424235.2 | J48: 5960315.1 | L48: backrest=yes, material=wood | M48: n2323592756
A49: BK042 | B49: Bank | C49: Bank | E49: prüfen | F49: OSM; im Luftbild nicht erkennbar | G49: 53.785902 | H49: 7.851547 | I49: 424335.2 | J49: 5960313.3 | L49: backrest=no | M49: n2322035378
A50: BK043 | B50: Bank | C50: Bank | E50: prüfen | F50: OSM; im Luftbild unsicher | G50: 53.786718 | H50: 7.860872 | I50: 424951 | J50: 5960394.1 | K50: Ruhezone I/32 | L50: backrest=yes | M50: n743377549
A51: BK044 | B51: Bank | C51: Bank | E51: sicher | F51: OSM + Luftbild | G51: 53.784977 | H51: 7.851307 | I51: 424317.7 | J51: 5960210.7 | L51: backrest=yes | M51: n2323592754
A52: BK045 | B52: Bank | C52: Bank | E52: prüfen | F52: OSM; im Luftbild nicht erkennbar | G52: 53.785244 | H52: 7.854412 | I52: 424522.8 | J52: 5960237.1 | L52: backrest=yes, material=wood, seats=4 | M52: n6549301865
A53: BK046 | B53: Bank | C53: Bank | E53: prüfen | F53: OSM; im Luftbild nicht erkennbar | G53: 53.78464 | H53: 7.85196 | I53: 424360.2 | J53: 5960172.5 | L53: backrest=no, material=wood, seats=5 | M53: n14085387067
A54: BK047 | B54: Bank | C54: Bank | E54: prüfen | F54: OSM; im Luftbild unsicher | G54: 53.784609 | H54: 7.852015 | I54: 424363.7 | J54: 5960169 | L54: backrest=no | M54: n2323592750
...

Sheet Pfade prüfen
A1: ID | B1: Wegtyp | C1: Info | D1: Quelle
A2: PF30127227 | B2: footway | D2: OSM; im Luftbild kaum sichtbar
A3: PF30127231 | B3: path | D3: OSM; im Luftbild kaum sichtbar
A4: PF43617471 | B4: path | D4: OSM; im Luftbild kaum sichtbar
A5: PF48203017 | B5: path | D5: OSM; im Luftbild kaum sichtbar
A6: PF60164676 | B6: footway | D6: OSM; im Luftbild kaum sichtbar
A7: PF81160977 | B7: path | D7: OSM; im Luftbild kaum sichtbar
A8: PF92511947 | B8: path | D8: OSM; im Luftbild kaum sichtbar
A9: PF181836894 | B9: footway | D9: OSM; im Luftbild kaum sichtbar
A10: PF223395862 | B10: path | D10: OSM; im Luftbild kaum sichtbar
A11: PF223421449 | B11: footway | D11: OSM; im Luftbild kaum sichtbar
A12: PF223421453 | B12: path | D12: OSM; im Luftbild kaum sichtbar
A13: PF223424291 | B13: path | D13: OSM; im Luftbild kaum sichtbar
... A25: PF1548445399 | B25: path | D25: OSM; im Luftbild kaum sichtbar
